Workbook

Sheet Read me
A1: AI ADOPTION FRAMEWORK
A2: How this workbook works
A3: Read this once. The short version: edit the peach cells, read the cream ones, and start on the Simulator sheet.
A6: What it is | B6: A live version of the AI Adoption Framework activity sheet. Every figure it reports is a formula — change an input and the charts, scores and verdicts move with it.
A7: Where to start | B7: Simulator is the one-screen view for a decision-maker: five assumptions, four numbers, a cash curve and a sensitivity grid. Dashboard is the full picture. The other sheets hold the detail.
A8: What to edit | B8: Only the peach cells are inputs. Cream cells are calculated — overwriting one breaks the chain.
A9: Financial figures | B9: The source workbook ships its Revenue vs Cost rows blank, so Financials opens on a worked example ($1.0M to build, $2.5M of benefit, $200k to run). Replace it with your own numbers.
A11: Three corrections | B11: The source workbook's own totals are wrong in three places. This version recomputes them and does not carry the stored results across:
A12: 1. Gate weights | B12: The question weights add to 240 and the section headers to 125, against a 0–100 scale. Sections are normalised to 100% and each question is weighted inside its own section. All fives now scores exactly 100.
A13: 2. Pillar scores | B13: The printed pillar summaries disagree with their own rows — People prints 2.11 where its nine items average 1.89. Recomputed from the rows.
A14: 3. Revenue maths | B14: Total Benefits was E+F+G+J, which drops Year 1, counts operating cost as a benefit and includes the Notes column; Net was H−B−G, subtracting operating cost twice. Here benefits = Y1 revenue + Y1 savings + Y2 revenue + Y2 savings, and net = benefits − implementation − operating.
A16: Use-case status | B16: The source sheet's Status column has no formula behind it. Process ≥ 2 and Tech ≥ 2 reproduces it on all twelve rows, so that is the readiness rule used here.
A17: Ramp-up | B17: On the Simulator, a slow ramp costs benefit rather than merely delaying it: monthly benefit is the full run-rate × MIN(1, month ÷ ramp). At a ramp of 1 the Simulator reproduces Financials exactly.

Sheet Dashboard
A1: OVERVIEW
A2: Where this stands
A3: Everything here is a formula over the other sheets — nothing is a stored total. Change anything on Pillars, Decision gate or Financials and this page follows.
A5: =Pillars!$B$64 | C5: =Pillars!$C$64-Pillars!$B$64 | E5: ='Decision gate'!$E$33 | G5: =IF(Financials!$B$12=0,"",Financials!$I$12/Financials!$B$12) | I5: =IF((Financials!$H$12-Financials!$G$12)<=0,"",Financials!$B$12/((Financials!$H$12-Financials!$G$12)/24)) | K5: =Financials!$I$12
A6: Readiness now, of 5 | C6: Gap to target | E6: Gate score of 100 | G6: ROI | I6: Payback, months | K6: Net benefit
A8: =LOOKUP('Decision gate'!$E$33,'Decision gate'!$A$37:$A$40,'Decision gate'!$B$37:$B$40)
A9: =LOOKUP('Decision gate'!$E$33,'Decision gate'!$A$37:$A$40,'Decision gate'!$C$37:$C$40)

Sheet Simulator
A1: BOARD VIEW
A2: What-if simulator
A3: Five assumptions in the peach cells. Every figure and both charts move the moment you change one. With every lever at its default this reproduces Financials and the Decision gate exactly.
A5: Assumption | B5: Value | C5: What it means | E5: =$D$45 | G5: =IF($B$13=0,"",$D$45/$B$13) | I5: =IF(COUNT($E$22:$E$45)=0,">24",MIN($E$22:$E$45)) | K5: =IF($B$13=0,"",SUM($B$22:$B$45)/$B$13) | M5: =MAX(0,MIN(100,'Decision gate'!$E$33+$B$10))
A6: Investment multiplier | B6: 1 | C6: x cost on Financials | E6: Net benefit over 24 months | G6: ROI | I6: Payback, months | K6: Benefit-cost ratio | M6: Readiness score
A7: Benefits realised | B7: 1 | C7: share of forecast actually won
A8: Ramp-up, months | B8: 1 | C8: months to full run-rate | E8: =LOOKUP(MAX(0,MIN(100,'Decision gate'!$E$33+$B$10)),'Decision gate'!$A$37:$A$40,'Decision gate'!$B$37:$B$40)
A9: Operating cost mult. | B9: 1 | C9: x running cost on Financials | E9: =LOOKUP(MAX(0,MIN(100,'Decision gate'!$E$33+$B$10)),'Decision gate'!$A$37:$A$40,'Decision gate'!$C$37:$C$40)
A10: Readiness shift, pts | B10: 0 | C10: added to the gate score
A12: Derived from the levers
A13: Implementation | B13: =Financials!$B$12*$B$6
A14: Benefits at full rate | B14: =Financials!$H$12*$B$7
A15: Operating cost | B15: =Financials!$G$12*$B$9
A16: Monthly run-rate | B16: =$B$14/24
A17: Monthly operating | B17: =$B$15/24
A19: Month by month — feeds the cash curve
A20: Month | B20: Benefit | C20: Operating | D20: Cumulative cash | E20: Crosses zero at
A21: 0 | B21: 0 | C21: 0 | D21: =-$B$13
A22: 1 | B22: =$B$16*MIN(1,A22/$B$8) | C22: =$B$17 | D22: =D21+B22-C22 | E22: =IF(AND(D22>=0,D21<0),A22-1+(-D21)/(D22-D21),"")
A23: 2 | B23: =$B$16*MIN(1,A23/$B$8) | C23: =$B$17 | D23: =D22+B23-C23 | E23: =IF(AND(D23>=0,D22<0),A23-1+(-D22)/(D23-D22),"")
A24: 3 | B24: =$B$16*MIN(1,A24/$B$8) | C24: =$B$17 | D24: =D23+B24-C24 | E24: =IF(AND(D24>=0,D23<0),A24-1+(-D23)/(D24-D23),"")
A25: 4 | B25: =$B$16*MIN(1,A25/$B$8) | C25: =$B$17 | D25: =D24+B25-C25 | E25: =IF(AND(D25>=0,D24<0),A25-1+(-D24)/(D25-D24),"")
A26: 5 | B26: =$B$16*MIN(1,A26/$B$8) | C26: =$B$17 | D26: =D25+B26-C26 | E26: =IF(AND(D26>=0,D25<0),A26-1+(-D25)/(D26-D25),"")
A27: 6 | B27: =$B$16*MIN(1,A27/$B$8) | C27: =$B$17 | D27: =D26+B27-C27 | E27: =IF(AND(D27>=0,D26<0),A27-1+(-D26)/(D27-D26),"")
A28: 7 | B28: =$B$16*MIN(1,A28/$B$8) | C28: =$B$17 | D28: =D27+B28-C28 | E28: =IF(AND(D28>=0,D27<0),A28-1+(-D27)/(D28-D27),"")
A29: 8 | B29: =$B$16*MIN(1,A29/$B$8) | C29: =$B$17 | D29: =D28+B29-C29 | E29: =IF(AND(D29>=0,D28<0),A29-1+(-D28)/(D29-D28),"")
A30: 9 | B30: =$B$16*MIN(1,A30/$B$8) | C30: =$B$17 | D30: =D29+B30-C30 | E30: =IF(AND(D30>=0,D29<0),A30-1+(-D29)/(D30-D29),"")
A31: 10 | B31: =$B$16*MIN(1,A31/$B$8) | C31: =$B$17 | D31: =D30+B31-C31 | E31: =IF(AND(D31>=0,D30<0),A31-1+(-D30)/(D31-D30),"")
A32: 11 | B32: =$B$16*MIN(1,A32/$B$8) | C32: =$B$17 | D32: =D31+B32-C32 | E32: =IF(AND(D32>=0,D31<0),A32-1+(-D31)/(D32-D31),"")
A33: 12 | B33: =$B$16*MIN(1,A33/$B$8) | C33: =$B$17 | D33: =D32+B33-C33 | E33: =IF(AND(D33>=0,D32<0),A33-1+(-D32)/(D33-D32),"")
... A45: 24 | B45: =$B$16*MIN(1,A45/$B$8) | C45: =$B$17 | D45: =D44+B45-C45 | E45: =IF(AND(D45>=0,D44<0),A45-1+(-D44)/(D45-D44),"")
A48: Net benefit if the assumptions miss
A49: Rows: share of forecast benefit actually captured. Columns: months to full run-rate. Investment and operating cost follow the levers above. Green is a positive case, red a loss.
A50: Benefits realised | B50: 1 mo | C50: 3 mo | D50: 6 mo | E50: 9 mo | F50: 12 mo | G50: 18 mo
A51: 1.2 | B51: =(Financials!$H$12*$A51/24)*SUMPRODUCT((ROW(INDIRECT("1:24"))/1)*((ROW(INDIRECT("1:24"))/1)<=1)+((ROW(INDIRECT("1:24"))/1)>1)*1)-Financials!$G$12*$B$9-Financials!$B$12*$B$6 | C51: =(Financials!$H$12*$A51/24)*SUMPRODUCT((ROW(INDIRECT("1:24"))/3)*((ROW(INDIRECT("1:24"))/3)<=1)+((ROW(INDIRECT("1:24"))/3)>1)*1)-Financials!$G$12*$B$9-Financials!$B$12*$B$6 | D51: =(Financials!$H$12*$A51/24)*SUMPRODUCT((ROW(INDIRECT("1:24"))/6)*((ROW(INDIRECT("1:24"))/6)<=1)+((ROW(INDIRECT("1:24"))/6)>1)*1)-Financials!$G$12*$B$9-Financials!$B$12*$B$6 | E51: =(Financials!$H$12*$A51/24)*SUMPRODUCT((ROW(INDIRECT("1:24"))/9)*((ROW(INDIRECT("1:24"))/9)<=1)+((ROW(INDIRECT("1:24"))/9)>1)*1)-Financials!$G$12*$B$9-Financials!$B$12*$B$6 | F51: =(Financials!$H$12*$A51/24)*SUMPRODUCT((ROW(INDIRECT("1:24"))/12)*((ROW(INDIRECT("1:24"))/12)<=1)+((ROW(INDIRECT("1:24"))/12)>1)*1)-Financials!$G$12*$B$9-Financials!$B$12*$B$6 | G51: =(Financials!$H$12*$A51/24)*SUMPRODUCT((ROW(INDIRECT("1:24"))/18)*((ROW(INDIRECT("1:24"))/18)<=1)+((ROW(INDIRECT("1:24"))/18)>1)*1)-Financials!$G$12*$B$9-Financials!$B$12*$B$6
A52: 1.1 | B52: =(Financials!$H$12*$A52/24)*SUMPRODUCT((ROW(INDIRECT("1:24"))/1)*((ROW(INDIRECT("1:24"))/1)<=1)+((ROW(INDIRECT("1:24"))/1)>1)*1)-Financials!$G$12*$B$9-Financials!$B$12*$B$6 | C52: =(Financials!$H$12*$A52/24)*SUMPRODUCT((ROW(INDIRECT("1:24"))/3)*((ROW(INDIRECT("1:24"))/3)<=1)+((ROW(INDIRECT("1:24"))/3)>1)*1)-Financials!$G$12*$B$9-Financials!$B$12*$B$6 | D52: =(Financials!$H$12*$A52/24)*SUMPRODUCT((ROW(INDIRECT("1:24"))/6)*((ROW(INDIRECT("1:24"))/6)<=1)+((ROW(INDIRECT("1:24"))/6)>1)*1)-Financials!$G$12*$B$9-Financials!$B$12*$B$6 | E52: =(Financials!$H$12*$A52/24)*SUMPRODUCT((ROW(INDIRECT("1:24"))/9)*((ROW(INDIRECT("1:24"))/9)<=1)+((ROW(INDIRECT("1:24"))/9)>1)*1)-Financials!$G$12*$B$9-Financials!$B$12*$B$6 | F52: =(Financials!$H$12*$A52/24)*SUMPRODUCT((ROW(INDIRECT("1:24"))/12)*((ROW(INDIRECT("1:24"))/12)<=1)+((ROW(INDIRECT("1:24"))/12)>1)*1)-Financials!$G$12*$B$9-Financials!$B$12*$B$6 | G52: =(Financials!$H$12*$A52/24)*SUMPRODUCT((ROW(INDIRECT("1:24"))/18)*((ROW(INDIRECT("1:24"))/18)<=1)+((ROW(INDIRECT("1:24"))/18)>1)*1)-Financials!$G$12*$B$9-Financials!$B$12*$B$6
A53: 1 | B53: =(Financials!$H$12*$A53/24)*SUMPRODUCT((ROW(INDIRECT("1:24"))/1)*((ROW(INDIRECT("1:24"))/1)<=1)+((ROW(INDIRECT("1:24"))/1)>1)*1)-Financials!$G$12*$B$9-Financials!$B$12*$B$6 | C53: =(Financials!$H$12*$A53/24)*SUMPRODUCT((ROW(INDIRECT("1:24"))/3)*((ROW(INDIRECT("1:24"))/3)<=1)+((ROW(INDIRECT("1:24"))/3)>1)*1)-Financials!$G$12*$B$9-Financials!$B$12*$B$6 | D53: =(Financials!$H$12*$A53/24)*SUMPRODUCT((ROW(INDIRECT("1:24"))/6)*((ROW(INDIRECT("1:24"))/6)<=1)+((ROW(INDIRECT("1:24"))/6)>1)*1)-Financials!$G$12*$B$9-Financials!$B$12*$B$6 | E53: =(Financials!$H$12*$A53/24)*SUMPRODUCT((ROW(INDIRECT("1:24"))/9)*((ROW(INDIRECT("1:24"))/9)<=1)+((ROW(INDIRECT("1:24"))/9)>1)*1)-Financials!$G$12*$B$9-Financials!$B$12*$B$6 | F53: =(Financials!$H$12*$A53/24)*SUMPRODUCT((ROW(INDIRECT("1:24"))/12)*((ROW(INDIRECT("1:24"))/12)<=1)+((ROW(INDIRECT("1:24"))/12)>1)*1)-Financials!$G$12*$B$9-Financials!$B$12*$B$6 | G53: =(Financials!$H$12*$A53/24)*SUMPRODUCT((ROW(INDIRECT("1:24"))/18)*((ROW(INDIRECT("1:24"))/18)<=1)+((ROW(INDIRECT("1:24"))/18)>1)*1)-Financials!$G$12*$B$9-Financials!$B$12*$B$6
A54: 0.9 | B54: =(Financials!$H$12*$A54/24)*SUMPRODUCT((ROW(INDIRECT("1:24"))/1)*((ROW(INDIRECT("1:24"))/1)<=1)+((ROW(INDIRECT("1:24"))/1)>1)*1)-Financials!$G$12*$B$9-Financials!$B$12*$B$6 | C54: =(Financials!$H$12*$A54/24)*SUMPRODUCT((ROW(INDIRECT("1:24"))/3)*((ROW(INDIRECT("1:24"))/3)<=1)+((ROW(INDIRECT("1:24"))/3)>1)*1)-Financials!$G$12*$B$9-Financials!$B$12*$B$6 | D54: =(Financials!$H$12*$A54/24)*SUMPRODUCT((ROW(INDIRECT("1:24"))/6)*((ROW(INDIRECT("1:24"))/6)<=1)+((ROW(INDIRECT("1:24"))/6)>1)*1)-Financials!$G$12*$B$9-Financials!$B$12*$B$6 | E54: =(Financials!$H$12*$A54/24)*SUMPRODUCT((ROW(INDIRECT("1:24"))/9)*((ROW(INDIRECT("1:24"))/9)<=1)+((ROW(INDIRECT("1:24"))/9)>1)*1)-Financials!$G$12*$B$9-Financials!$B$12*$B$6 | F54: =(Financials!$H$12*$A54/24)*SUMPRODUCT((ROW(INDIRECT("1:24"))/12)*((ROW(INDIRECT("1:24"))/12)<=1)+((ROW(INDIRECT("1:24"))/12)>1)*1)-Financials!$G$12*$B$9-Financials!$B$12*$B$6 | G54: =(Financials!$H$12*$A54/24)*SUMPRODUCT((ROW(INDIRECT("1:24"))/18)*((ROW(INDIRECT("1:24"))/18)<=1)+((ROW(INDIRECT("1:24"))/18)>1)*1)-Financials!$G$12*$B$9-Financials!$B$12*$B$6
A55: 0.8 | B55: =(Financials!$H$12*$A55/24)*SUMPRODUCT((ROW(INDIRECT("1:24"))/1)*((ROW(INDIRECT("1:24"))/1)<=1)+((ROW(INDIRECT("1:24"))/1)>1)*1)-Financials!$G$12*$B$9-Financials!$B$12*$B$6 | C55: =(Financials!$H$12*$A55/24)*SUMPRODUCT((ROW(INDIRECT("1:24"))/3)*((ROW(INDIRECT("1:24"))/3)<=1)+((ROW(INDIRECT("1:24"))/3)>1)*1)-Financials!$G$12*$B$9-Financials!$B$12*$B$6 | D55: =(Financials!$H$12*$A55/24)*SUMPRODUCT((ROW(INDIRECT("1:24"))/6)*((ROW(INDIRECT("1:24"))/6)<=1)+((ROW(INDIRECT("1:24"))/6)>1)*1)-Financials!$G$12*$B$9-Financials!$B$12*$B$6 | E55: =(Financials!$H$12*$A55/24)*SUMPRODUCT((ROW(INDIRECT("1:24"))/9)*((ROW(INDIRECT("1:24"))/9)<=1)+((ROW(INDIRECT("1:24"))/9)>1)*1)-Financials!$G$12*$B$9-Financials!$B$12*$B$6 | F55: =(Financials!$H$12*$A55/24)*SUMPRODUCT((ROW(INDIRECT("1:24"))/12)*((ROW(INDIRECT("1:24"))/12)<=1)+((ROW(INDIRECT("1:24"))/12)>1)*1)-Financials!$G$12*$B$9-Financials!$B$12*$B$6 | G55: =(Financials!$H$12*$A55/24)*SUMPRODUCT((ROW(INDIRECT("1:24"))/18)*((ROW(INDIRECT("1:24"))/18)<=1)+((ROW(INDIRECT("1:24"))/18)>1)*1)-Financials!$G$12*$B$9-Financials!$B$12*$B$6
A56: 0.7 | B56: =(Financials!$H$12*$A56/24)*SUMPRODUCT((ROW(INDIRECT("1:24"))/1)*((ROW(INDIRECT("1:24"))/1)<=1)+((ROW(INDIRECT("1:24"))/1)>1)*1)-Financials!$G$12*$B$9-Financials!$B$12*$B$6 | C56: =(Financials!$H$12*$A56/24)*SUMPRODUCT((ROW(INDIRECT("1:24"))/3)*((ROW(INDIRECT("1:24"))/3)<=1)+((ROW(INDIRECT("1:24"))/3)>1)*1)-Financials!$G$12*$B$9-Financials!$B$12*$B$6 | D56: =(Financials!$H$12*$A56/24)*SUMPRODUCT((ROW(INDIRECT("1:24"))/6)*((ROW(INDIRECT("1:24"))/6)<=1)+((ROW(INDIRECT("1:24"))/6)>1)*1)-Financials!$G$12*$B$9-Financials!$B$12*$B$6 | E56: =(Financials!$H$12*$A56/24)*SUMPRODUCT((ROW(INDIRECT("1:24"))/9)*((ROW(INDIRECT("1:24"))/9)<=1)+((ROW(INDIRECT("1:24"))/9)>1)*1)-Financials!$G$12*$B$9-Financials!$B$12*$B$6 | F56: =(Financials!$H$12*$A56/24)*SUMPRODUCT((ROW(INDIRECT("1:24"))/12)*((ROW(INDIRECT("1:24"))/12)<=1)+((ROW(INDIRECT("1:24"))/12)>1)*1)-Financials!$G$12*$B$9-Financials!$B$12*$B$6 | G56: =(Financials!$H$12*$A56/24)*SUMPRODUCT((ROW(INDIRECT("1:24"))/18)*((ROW(INDIRECT("1:24"))/18)<=1)+((ROW(INDIRECT("1:24"))/18)>1)*1)-Financials!$G$12*$B$9-Financials!$B$12*$B$6
...

Sheet Pillars
A1: STEP 1
A2: Pillar assessment
A3: Score each area 0–5 as it is today and where it needs to be. Averages, gaps and every chart update as you type. Peach cells are yours; cream cells are calculated.
A5: People
A6: Assessment area | B6: Now | C6: Target | D6: Gap | E6: Actions required | F6: Owner
A7: Skills & Competencies | B7: 2 | C7: 5 | D7: =C7-B7 | E7: Upskilling programs, AI certification courses, role-based training | F7: HR Lead
A8: Change Management Readiness | B8: 2 | C8: 4 | D8: =C8-B8 | E8: Adoption incentive program, feedback loops, success story sharing | F8: Change Manager
A9: Leadership Buy-in | B9: 4 | C9: 5 | D9: =C9-B9 | E9: Executive alignment sessions, vision reinforcement, quarterly reviews | F9: CIO/CDO
A10: Talent Attraction/Retention | B10: 2 | C10: 4 | D10: =C10-B10 | E10: Competitive compensation, career pathing, innovation roles | F10: HR Lead
A11: Cultural Mindset | B11: 3 | C11: 5 | D11: =C11-B11 | E11: Innovation culture initiatives, hackathons, experimentation labs | F11: CEO/COO
A12: Team Collaboration | B12: 3 | C12: 4 | D12: =C12-B12 | E12: Cross-functional AI pods, shared OKRs, collaboration tools | F12: Team Leads
A13: Adoption Incentive Structure | B13: 0 | C13: 5 | D13: =C13-B13 | E13: Design & launch bonus/promotion criteria tied to AI adoption metrics | F13: HR/Change Manager
A14: User Adoption Metrics (WAU/CSAT) | B14: 1 | C14: 5 | D14: =C14-B14 | E14: Implement tracking for weekly active users, CSAT >4.2/5 target | F14: Change Manager
A15: Center of Excellence Readiness | B15: 0 | C15: 5 | D15: =C15-B15 | E15: Define CoE structure, appoint Chief AI Officer, budget allocation | F15: CIO
A16: People average | B16: =AVERAGE(B7:B15) | C16: =AVERAGE(C7:C15) | D16: =C16-B16
A18: Process
A19: Assessment area | B19: Now | C19: Target | D19: Gap | E19: Actions required | F19: Owner
A20: Decision-Making Frameworks | B20: 2 | C20: 5 | D20: =C20-B20 | E20: Define AI decision tree, governance model, approval workflows | F20: COO
A21: Data Governance | B21: 2 | C21: 4 | D21: =C21-B21 | E21: Data strategy, quality standards, ownership model, stewardship roles | F21: CDO
A22: Risk Management | B22: 3 | C22: 5 | D22: =C22-B22 | E22: Risk assessment, mitigation framework, risk register, escalation paths | F22: Risk Officer
A23: Process Standardization | B23: 2 | C23: 4 | D23: =C23-B23 | E23: Document core processes, create playbooks, standardized templates | F23: Process Lead
A24: Governance Structure & RACI | B24: 2 | C24: 5 | D24: =C24-B24 | E24: AI governance committee, clear RACI matrix, decision authority | F24: CIO
A25: Vendor Management | B25: 3 | C25: 4 | D25: =C25-B25 | E25: Partner ecosystem, SLA definitions, vendor risk assessments | F25: Procurement
A26: Compliance & Ethics | B26: 2 | C26: 5 | D26: =C26-B26 | E26: Ethics board, responsible AI framework, regulatory compliance plan | F26: Legal/Risk
A27: Change Management Processes | B27: 1 | C27: 5 | D27: =C27-B27 | E27: Adoption incentives, feedback loops, communication cadence, issue tracking | F27: Change Manager
A28: Responsible AI Governance Gates | B28: 0 | C28: 5 | D28: =C28-B28 | E28: Ethics review process, bias assessment, model card requirements, audit trails | F28: Legal/Ethics
A29: Process average | B29: =AVERAGE(B20:B28) | C29: =AVERAGE(C20:C28) | D29: =C29-B29
A31: Technology
A32: Assessment area | B32: Now | C32: Target | D32: Gap | E32: Actions required | F32: Owner
A33: Infrastructure & Cloud | B33: 2 | C33: 5 | D33: =C33-B33 | E33: Cloud migration, scalable infrastructure, multi-region capability | F33: IT Lead
A34: Data & Analytics Capability | B34: 2 | C34: 5 | D34: =C34-B34 | E34: Data warehouse, analytics platform, real-time streaming | F34: Data Lead
A35: AI/ML Tools & Platforms | B35: 1 | C35: 5 | D35: =C35-B35 | E35: ML platform selection, MLOps setup, model registry | F35: Data Lead
A36: MLOps & Deployment Pipeline | B36: 1 | C36: 5 | D36: =C36-B36 | E36: CI/CD for ML, automated testing, model versioning, rollback capability | F36: DevOps Lead
A37: Integration & APIs | B37: 2 | C37: 4 | D37: =C37-B37 | E37: API-first architecture, system integration, microservices | F37: Tech Lead
A38: Security & Data Privacy | B38: 3 | C38: 5 | D38: =C38-B38 | E38: Security hardening, encryption, GDPR, access controls, audit logs | F38: Security Lead
A39: Monitoring & Observability | B39: 1 | C39: 4 | D39: =C39-B39 | E39: Logging, monitoring, alerting, drift detection, performance tracking | F39: DevOps Lead
A40: Model Monitoring & Drift Detection | B40: 0 | C40: 5 | D40: =C40-B40 | E40: Automated drift detection, performance degradation alerts, retraining triggers | F40: Data Lead
A41: Vendor Technology Stack | B41: 2 | C41: 4 | D41: =C41-B41 | E41: Tool evaluation, licensing, partnerships, multi-vendor strategy | F41: Procurement
A42: Technology average | B42: =AVERAGE(B33:B41) | C42: =AVERAGE(C33:C41) | D42: =C42-B42
A44: Responsible AI
...

Sheet Decision gate
A1: STEP 2
A2: Decision gate
A3: Score each question 0–5 in column E. Section weights are normalised to 100%, so the total is a true score out of 100 — the source sheet’s weights add to 240 and 125, which it scored against 100.
A5: Section | B5: Question | C5: Scoring criteria | D5: Weight | E5: Score
A6: STRATEGIC ALIGNMENT | B6: Does the AI initiative align with business goals? | C6: Strong alignment=5, Moderate=3, Low=1 | D6: 20 | E6: 0
A7: PEOPLE READINESS | B7: Do we have skills and change management capability? | C7: Full capability=5, Partial=3, None=1 | D7: 15 | E7: 0
A8: PEOPLE READINESS | B8: Leadership support and buy-in present? | C8: Strong support=5, Moderate=3, Low=1 | D8: 15 | E8: 0
A9: PROCESS MATURITY | B9: Are relevant processes documented and optimized? | C9: Documented & optimized=5, Partial=3, Ad-hoc=1 | D9: 20 | E9: 0
A10: PROCESS MATURITY | B10: Data governance and quality standards exist? | C10: Comprehensive=5, Partial=3, None=1 | D10: 15 | E10: 0
A11: PROCESS MATURITY | B11: Do we have risk & compliance framework? | C11: Complete framework=5, Partial=3, None=1 | D11: 10 | E11: 0
A12: TECHNOLOGY INFRASTRUCTURE | B12: Is cloud infrastructure and scalability available? | C12: Fully ready=5, Partial=3, Not ready=1 | D12: 15 | E12: 0
A13: TECHNOLOGY INFRASTRUCTURE | B13: Do we have data & analytics platform? | C13: Advanced platform=5, Basic=3, None=1 | D13: 20 | E13: 0
A14: TECHNOLOGY INFRASTRUCTURE | B14: ML tools and MLOps capability in place? | C14: Full capability=5, Partial=3, None=1 | D14: 15 | E14: 0
A15: RESPONSIBLE AI READINESS | B15: Bias detection & fairness assessment in place? | C15: Comprehensive=5, Basic=3, None=1 | D15: 10 | E15: 0
A16: RESPONSIBLE AI READINESS | B16: Ethics governance framework established? | C16: Formal board + processes=5, Informal=3, None=1 | D16: 15 | E16: 0
A17: RESPONSIBLE AI READINESS | B17: Privacy & compliance risk mitigated? | C17: Full assessment done=5, Partial=3, None=1 | D17: 10 | E17: 0
... A22: CHANGE MANAGEMENT READINESS | B22: User adoption tracking in place (WAU/CSAT)? | C22: Comprehensive dashboard=5, Manual tracking=3, None=1 | D22: 10 | E22: 0
A24: Section scoring
A25: Section | B25: Stated weight % | C25: Normalised % | D25: Section score 0-1 | E25: Points of 100
A26: STRATEGIC ALIGNMENT | B26: 20 | C26: =B26/SUM($B$26:$B$32) | D26: =IFERROR(SUMPRODUCT(($A$6:$A$22=A26)*$D$6:$D$22*$E$6:$E$22)/(5*SUMIF($A$6:$A$22,A26,$D$6:$D$22)),0) | E26: =C26*D26*100
A27: PEOPLE READINESS | B27: 15 | C27: =B27/SUM($B$26:$B$32) | D27: =IFERROR(SUMPRODUCT(($A$6:$A$22=A27)*$D$6:$D$22*$E$6:$E$22)/(5*SUMIF($A$6:$A$22,A27,$D$6:$D$22)),0) | E27: =C27*D27*100
A28: PROCESS MATURITY | B28: 20 | C28: =B28/SUM($B$26:$B$32) | D28: =IFERROR(SUMPRODUCT(($A$6:$A$22=A28)*$D$6:$D$22*$E$6:$E$22)/(5*SUMIF($A$6:$A$22,A28,$D$6:$D$22)),0) | E28: =C28*D28*100
A29: TECHNOLOGY INFRASTRUCTURE | B29: 25 | C29: =B29/SUM($B$26:$B$32) | D29: =IFERROR(SUMPRODUCT(($A$6:$A$22=A29)*$D$6:$D$22*$E$6:$E$22)/(5*SUMIF($A$6:$A$22,A29,$D$6:$D$22)),0) | E29: =C29*D29*100
A30: RESPONSIBLE AI READINESS | B30: 15 | C30: =B30/SUM($B$26:$B$32) | D30: =IFERROR(SUMPRODUCT(($A$6:$A$22=A30)*$D$6:$D$22*$E$6:$E$22)/(5*SUMIF($A$6:$A$22,A30,$D$6:$D$22)),0) | E30: =C30*D30*100
A31: BUSINESS CASE | B31: 20 | C31: =B31/SUM($B$26:$B$32) | D31: =IFERROR(SUMPRODUCT(($A$6:$A$22=A31)*$D$6:$D$22*$E$6:$E$22)/(5*SUMIF($A$6:$A$22,A31,$D$6:$D$22)),0) | E31: =C31*D31*100
A32: CHANGE MANAGEMENT READINESS | B32: 10 | C32: =B32/SUM($B$26:$B$32) | D32: =IFERROR(SUMPRODUCT(($A$6:$A$22=A32)*$D$6:$D$22*$E$6:$E$22)/(5*SUMIF($A$6:$A$22,A32,$D$6:$D$22)),0) | E32: =C32*D32*100
A33: TOTAL SCORE | B33: =LOOKUP('Decision gate'!$E$33,'Decision gate'!$A$37:$A$40,'Decision gate'!$B$37:$B$40) | E33: =SUM(E26:E32)
A35: Scoring bands
A36: From | B36: Verdict | C36: Action
A37: 0 | B37: NOT READY - BUILD FOUNDATION FIRST | C37: Stop - Halt; redesign or defer 6+ months
A38: 50 | B38: REQUIRES SIGNIFICANT PREPARATION | C38: Red Light - Delay 4-6 weeks; address major gaps
A39: 65 | B39: READY WITH MINOR PREPARATORY STEPS | C39: Yellow Light - Address 2-3 gaps, then proceed
A40: 80 | B40: READY FOR IMMEDIATE IMPLEMENTATION | C40: Green Light - Proceed full speed

Sheet Financials
A1: STEP 3
A2: Financials
A3: Enter cost and benefit per initiative in the peach cells. Benefits and net use the corrected formulas: benefits = Y1 revenue + Y1 savings + Y2 revenue + Y2 savings, net = benefits − implementation − operating.
A5: Initiative | B5: Implementation | C5: Y1 revenue | D5: Y1 savings | E5: Y2 revenue | F5: Y2 savings | G5: Operating | H5: Benefits | I5: Net benefit | J5: Notes
A6: GenAI Process Automation | B6: 300000 | C6: 150000 | D6: 250000 | E6: 300000 | F6: 250000 | G6: 60000 | H6: =SUM(C6:F6) | I6: =H6-B6-G6 | J6: example figures — replace
A7: Predictive Analytics | B7: 220000 | C7: 100000 | D7: 120000 | E7: 200000 | F7: 130000 | G7: 45000 | H7: =SUM(C7:F7) | I7: =H7-B7-G7 | J7: example figures — replace
A8: Customer AI Assistant | B8: 180000 | C8: 90000 | D8: 110000 | E8: 150000 | F8: 100000 | G8: 40000 | H8: =SUM(C8:F8) | I8: =H8-B8-G8 | J8: example figures — replace
A9: Document Intelligence | B9: 130000 | C9: 40000 | D9: 90000 | E9: 60000 | F9: 70000 | G9: 25000 | H9: =SUM(C9:F9) | I9: =H9-B9-G9 | J9: example figures — replace
A10: Code Generation | B10: 100000 | C10: 20000 | D10: 60000 | E10: 40000 | F10: 50000 | G10: 18000 | H10: =SUM(C10:F10) | I10: =H10-B10-G10 | J10: example figures — replace
A11: Risk Assessment AI | B11: 70000 | C11: 20000 | D11: 40000 | E11: 30000 | F11: 30000 | G11: 12000 | H11: =SUM(C11:F11) | I11: =H11-B11-G11 | J11: example figures — replace
A12: TOTALS | B12: =SUM(B6:B11) | C12: =SUM(C6:C11) | D12: =SUM(D6:D11) | E12: =SUM(E6:E11) | F12: =SUM(F6:F11) | G12: =SUM(G6:G11) | H12: =SUM(H6:H11) | I12: =SUM(I6:I11)
A14: Programme metrics
A15: =Financials!$B$12 | C15: =Financials!$H$12 | E15: =Financials!$I$12 | G15: =IF(Financials!$B$12=0,"",Financials!$I$12/Financials!$B$12) | I15: =IF(Financials!$B$12=0,"",Financials!$H$12/Financials!$B$12) | K15: =IF((Financials!$H$12-Financials!$G$12)<=0,"",Financials!$B$12/((Financials!$H$12-Financials!$G$12)/24))
A16: Total investment | C16: 2-year benefits | E16: Net benefit | G16: ROI | I16: Benefit-cost ratio | K16: Payback, months

Sheet Use cases
A1: STEP 4
A2: Use-case portfolio
A3: Value blends return against risk. A use case can start when process and tech are both 2 or more — the rule that reproduces the source sheet’s own Status column on all twelve rows. Score the peach cells; value, readiness and the verdict follow.
A5: ID | B5: Use case | C5: Department | D5: People | E5: Process | F5: Tech | G5: AI risk | H5: Portfolio risk | I5: ROI x | J5: Value | K5: Readiness | L5: Verdict | N5: Readiness | O5: ROI x
A6: UC-001 | B6: Customer Service Chatbot | C6: Customer Service | D6: 3 | E6: 3 | F6: 2 | G6: Medium | H6: Medium | I6: 2.5 | J6: =MAX(0,MIN(100,MIN(I6,5)/5*70+(4-(IF(ISNUMBER(SEARCH("high",G6)),2,IF(ISNUMBER(SEARCH("medium",G6)),1,0))+IF(ISNUMBER(SEARCH("high",H6)),2,IF(ISNUMBER(SEARCH("medium",H6)),1,0))))/4*30)) | K6: =IF(AND(E6>=2,F6>=2),"Ready","Not yet") | L6: =IF(K6="Not yet","Needs foundation",IF(J6>=60,"Start now","Schedule")) | N6: =AVERAGE(D6:F6) | O6: =I6
A7: UC-002 | B7: Predictive Analytics - Demand | C7: Operations | D7: 2 | E7: 2 | F7: 1 | G7: Low | H7: Medium | I7: 3 | J7: =MAX(0,MIN(100,MIN(I7,5)/5*70+(4-(IF(ISNUMBER(SEARCH("high",G7)),2,IF(ISNUMBER(SEARCH("medium",G7)),1,0))+IF(ISNUMBER(SEARCH("high",H7)),2,IF(ISNUMBER(SEARCH("medium",H7)),1,0))))/4*30)) | K7: =IF(AND(E7>=2,F7>=2),"Ready","Not yet") | L7: =IF(K7="Not yet","Needs foundation",IF(J7>=60,"Start now","Schedule")) | N7: =AVERAGE(D7:F7) | O7: =I7
A8: UC-003 | B8: Fraud Detection System | C8: Finance | D8: 3 | E8: 3 | F8: 2 | G8: High | H8: Low | I8: 4 | J8: =MAX(0,MIN(100,MIN(I8,5)/5*70+(4-(IF(ISNUMBER(SEARCH("high",G8)),2,IF(ISNUMBER(SEARCH("medium",G8)),1,0))+IF(ISNUMBER(SEARCH("high",H8)),2,IF(ISNUMBER(SEARCH("medium",H8)),1,0))))/4*30)) | K8: =IF(AND(E8>=2,F8>=2),"Ready","Not yet") | L8: =IF(K8="Not yet","Needs foundation",IF(J8>=60,"Start now","Schedule")) | N8: =AVERAGE(D8:F8) | O8: =I8
A9: UC-004 | B9: HR Talent Analytics | C9: HR | D9: 2 | E9: 1 | F9: 1 | G9: High (Privacy/Bias) | H9: High | I9: 1.8 | J9: =MAX(0,MIN(100,MIN(I9,5)/5*70+(4-(IF(ISNUMBER(SEARCH("high",G9)),2,IF(ISNUMBER(SEARCH("medium",G9)),1,0))+IF(ISNUMBER(SEARCH("high",H9)),2,IF(ISNUMBER(SEARCH("medium",H9)),1,0))))/4*30)) | K9: =IF(AND(E9>=2,F9>=2),"Ready","Not yet") | L9: =IF(K9="Not yet","Needs foundation",IF(J9>=60,"Start now","Schedule")) | N9: =AVERAGE(D9:F9) | O9: =I9
A10: UC-005 | B10: Sales Forecasting | C10: Sales | D10: 3 | E10: 2 | F10: 2 | G10: Low | H10: Medium | I10: 2 | J10: =MAX(0,MIN(100,MIN(I10,5)/5*70+(4-(IF(ISNUMBER(SEARCH("high",G10)),2,IF(ISNUMBER(SEARCH("medium",G10)),1,0))+IF(ISNUMBER(SEARCH("high",H10)),2,IF(ISNUMBER(SEARCH("medium",H10)),1,0))))/4*30)) | K10: =IF(AND(E10>=2,F10>=2),"Ready","Not yet") | L10: =IF(K10="Not yet","Needs foundation",IF(J10>=60,"Start now","Schedule")) | N10: =AVERAGE(D10:F10) | O10: =I10
A11: UC-006 | B11: Supply Chain Optimization | C11: Supply Chain | D11: 2 | E11: 1 | F11: 1 | G11: Medium | H11: High | I11: 3.5 | J11: =MAX(0,MIN(100,MIN(I11,5)/5*70+(4-(IF(ISNUMBER(SEARCH("high",G11)),2,IF(ISNUMBER(SEARCH("medium",G11)),1,0))+IF(ISNUMBER(SEARCH("high",H11)),2,IF(ISNUMBER(SEARCH("medium",H11)),1,0))))/4*30)) | K11: =IF(AND(E11>=2,F11>=2),"Ready","Not yet") | L11: =IF(K11="Not yet","Needs foundation",IF(J11>=60,"Start now","Schedule")) | N11: =AVERAGE(D11:F11) | O11: =I11
A12: UC-007 | B12: Document Processing & RPA | C12: Operations | D12: 2 | E12: 2 | F12: 2 | G12: Low | H12: Low | I12: 2.2 | J12: =MAX(0,MIN(100,MIN(I12,5)/5*70+(4-(IF(ISNUMBER(SEARCH("high",G12)),2,IF(ISNUMBER(SEARCH("medium",G12)),1,0))+IF(ISNUMBER(SEARCH("high",H12)),2,IF(ISNUMBER(SEARCH("medium",H12)),1,0))))/4*30)) | K12: =IF(AND(E12>=2,F12>=2),"Ready","Not yet") | L12: =IF(K12="Not yet","Needs foundation",IF(J12>=60,"Start now","Schedule")) | N12: =AVERAGE(D12:F12) | O12: =I12
A13: UC-008 | B13: Product Recommendation Engine | C13: Marketing | D13: 2 | E13: 2 | F13: 1 | G13: High (Fairness) | H13: Medium | I13: 2.8 | J13: =MAX(0,MIN(100,MIN(I13,5)/5*70+(4-(IF(ISNUMBER(SEARCH("high",G13)),2,IF(ISNUMBER(SEARCH("medium",G13)),1,0))+IF(ISNUMBER(SEARCH("high",H13)),2,IF(ISNUMBER(SEARCH("medium",H13)),1,0))))/4*30)) | K13: =IF(AND(E13>=2,F13>=2),"Ready","Not yet") | L13: =IF(K13="Not yet","Needs foundation",IF(J13>=60,"Start now","Schedule")) | N13: =AVERAGE(D13:F13) | O13: =I13
A14: UC-009 | B14: Pricing Optimization | C14: Revenue | D14: 2 | E14: 2 | F14: 1 | G14: Medium | H14: Medium | I14: 3.2 | J14: =MAX(0,MIN(100,MIN(I14,5)/5*70+(4-(IF(ISNUMBER(SEARCH("high",G14)),2,IF(ISNUMBER(SEARCH("medium",G14)),1,0))+IF(ISNUMBER(SEARCH("high",H14)),2,IF(ISNUMBER(SEARCH("medium",H14)),1,0))))/4*30)) | K14: =IF(AND(E14>=2,F14>=2),"Ready","Not yet") | L14: =IF(K14="Not yet","Needs foundation",IF(J14>=60,"Start now","Schedule")) | N14: =AVERAGE(D14:F14) | O14: =I14
A15: UC-010 | B15: Maintenance Prediction | C15: Operations | D15: 1 | E15: 1 | F15: 1 | G15: Low | H15: High | I15: 2.5 | J15: =MAX(0,MIN(100,MIN(I15,5)/5*70+(4-(IF(ISNUMBER(SEARCH("high",G15)),2,IF(ISNUMBER(SEARCH("medium",G15)),1,0))+IF(ISNUMBER(SEARCH("high",H15)),2,IF(ISNUMBER(SEARCH("medium",H15)),1,0))))/4*30)) | K15: =IF(AND(E15>=2,F15>=2),"Ready","Not yet") | L15: =IF(K15="Not yet","Needs foundation",IF(J15>=60,"Start now","Schedule")) | N15: =AVERAGE(D15:F15) | O15: =I15
A16: UC-011 | B16: Employee Experience Analytics | C16: HR | D16: 2 | E16: 1 | F16: 1 | G16: High (Privacy/Bias) | H16: High | I16: 1.5 | J16: =MAX(0,MIN(100,MIN(I16,5)/5*70+(4-(IF(ISNUMBER(SEARCH("high",G16)),2,IF(ISNUMBER(SEARCH("medium",G16)),1,0))+IF(ISNUMBER(SEARCH("high",H16)),2,IF(ISNUMBER(SEARCH("medium",H16)),1,0))))/4*30)) | K16: =IF(AND(E16>=2,F16>=2),"Ready","Not yet") | L16: =IF(K16="Not yet","Needs foundation",IF(J16>=60,"Start now","Schedule")) | N16: =AVERAGE(D16:F16) | O16: =I16
A17: UC-012 | B17: Market Intelligence & News Analysis | C17: Strategy | D17: 2 | E17: 2 | F17: 2 | G17: Medium | H17: Medium | I17: 1.8 | J17: =MAX(0,MIN(100,MIN(I17,5)/5*70+(4-(IF(ISNUMBER(SEARCH("high",G17)),2,IF(ISNUMBER(SEARCH("medium",G17)),1,0))+IF(ISNUMBER(SEARCH("high",H17)),2,IF(ISNUMBER(SEARCH("medium",H17)),1,0))))/4*30)) | K17: =IF(AND(E17>=2,F17>=2),"Ready","Not yet") | L17: =IF(K17="Not yet","Needs foundation",IF(J17>=60,"Start now","Schedule")) | N17: =AVERAGE(D17:F17) | O17: =I17

Sheet Gen-Ai Assessment
A1: Ai-GenAI Strategic Assessment Framework
A2: 1. STRATEGIC ASSESSMENT TEMPLATE
A3: Executive Summary Assessment Matrix
A4: Organization:
A5: Assessment Date:
A6: Assessed by:
A7: Next Review Date:
A8: Phase 1: Strategic Alignment Assessment
A9: A. Business Objectives Mapping
A10: Business Objective | B10: Current State | C10: GenAI Opportunity | D10: Impact Score (1-5) | E10: Feasibility Score (1-5)
A11: Revenue Growth
A12: Cost Optimization
A13: Customer Experience
A14: Operational Efficiency
A15: Innovation & R&D
A16: Market Differentiation
A17: Total Strategic Alignment Score: | B17: ___/30
A18: B. Competitive Advantage Analysis
A19: Rate each area from 1 (No advantage) to 5 (Significant advantage):
A20: Differentiation potential through GenAI: | B20: __________________
A21: First-mover advantage opportunity: | B21: __________________
A22: Customer value proposition enhancement: | B22: __________________
A23: Cost leadership potential: | B23: __________________
A24: Innovation acceleration capability: | B24: __________________
A25: Total Competitive Score: | B25: ______/25
A26: Phase 2: Organizational Readiness Assessment
A27: A. Data Infrastructure Maturity
A28: Component | B28: Current State | C28: Required State | D28: Gap Analysis | E28: Action Required
A29: Data Quality | B29: 1-2-3-4-5 | C29: 1-2-3-4-5
A30: Data Governance | B30: 1-2-3-4-5 | C30: 1-2-3-4-5
A31: Data Architecture | B31: 1-2-3-4-5 | C31: 1-2-3-4-5
A32: Data Security | B32: 1-2-3-4-5 | C32: 1-2-3-4-5
A33: Cloud Readiness | B33: 1-2-3-4-5 | C33: 1-2-3-4-5
A34: Data Readiness Score: | B34: ___/25
A35: B. Technical Capability Assessment
A36: AI/ML expertise in-house: | B36: Low / Medium / High
A37: Technology infrastructure scalability: | B37: Low / Medium / High
A38: Integration capabilities: | B38: Low / Medium / High
A39: Development resources: | B39: Limited / Adequate / Abundant
A40: Vendor management capability: | B40: Developing / Competent / Expert
...

Sheet GenAI ROI Calculation Framework
A1: Executive Summary
A2: This comprehensive framework enables organizations to calculate, track, and optimize the Return on Investment (ROI) for GenAI initiatives. It includes both quantitative metrics and qualitative benefits assessment.
A3: A. ROI Calculation Methodology
A4: Core ROI Formula | B4: ROI = (Net Benefits - Total Investment) / Total Investment × 100
A5: Where:
A6: Net Benefits | B6: = Total Benefits - Total Costs (operational, ongoing)
A7: Total Investment | B7: = Initial + Implementation + Ongoing Costs
A8: Alternative ROI Metrics
B9: 1. Net Present Value (NPV) | C9: NPV = Σ [(Benefits - Costs) / (1 + Discount Rate)^Year]
A10: 2. Payback Period | B10: Payback Period = Initial Investment / Annual Net Cash Flow
A11: 3. Internal Rate of Return (IRR) | B11: IRR = Discount rate where NPV = 0
A12: B. Cost Component Analysis
A13: 1. Initial Investment Costs
A14: Cost Category | B14: Year 1 | C14: Description | D14: Amount ($)
A15: Technology Infrastructure
A16: - Cloud platform setup | C16: Initial cloud services setup
A17: - Hardware/servers | C17: Additional computing resources
A18: - Software licensing | C18: AI platform licenses
A19: Implementation Services
A20: - Consulting fees | C20: External implementation support
A21: - System integration | C21: Integration with existing systems
A22: - Data migration | C22: Moving/preparing data
A23: Internal Resources
A24: - Project management | C24: Internal PM costs
A25: - Technical team time | C25: Development resources
A26: - Business analyst time | C26: Requirements gathering
A27: Training & Development
A28: - Employee training | C28: Skills development programs
A29: - Certification programs | C29: Technical certifications
A30: - Change management | C30: Organizational change support
A31: Total Initial Investment: | B31: $
A32: 2. Ongoing Operational Costs (Annual)
A33: Cost Category | B33: Annual Amount | C33: Notes
A34: Technology Costs
A35: - Cloud services | C35: Monthly/annual subscriptions
A36: - Software licenses | C36: Recurring license fees
A37: - Data storage | C37: Storage and processing costs
A38: - Security & compliance | C38: Additional security measures
A39: Personnel Costs
A40: - AI specialists | C40: Salary + benefits
...

Sheet Partnership Negotiation Guide
A1: GenAI Partnership Negotiation Guide
A2: PARTNERSHIP NEGOTIATION GUIDE & TEMPLATE
A3: Executive Overview | B3: This guide provides a structured template for negotiating GenAI partnerships, with a filled-in example tailored to the
A4: A. Negotiation Preparation Checklist
A5: Task | B5: Complete | C5: Notes
A6: Define strategic objectives | B6: ☐ | C6: Improve customer personalization & inventory optimization
A7: Identify potential partners | B7: ☐ | C7: Shortlisted: AIStyle, TrendAI, PersonaFit
A8: Assemble negotiation team | B8: ☐ | C8: CEO, CIO, Head of Merchandising, Legal Counsel
A9: Gather market intelligence | B9: ☐ | C9: Benchmark retail AI deals, competitor analysis
A10: Determine BATNA (Best Alternative to Negotiated Agreement) | B10: ☐ | C10: In-house AI pilot with existing data science team
A11: Establish authority and decision rights | B11: ☐ | C11: CIO leads; final approval by CEO & Board
A12: B. Negotiation Framework
A13: 1. Value Creation & Shared Objectives
A14: Partner Goal | B14: Company Goal | C14: Mutual Value
A15: Expand AI platform into fashion vertical | B15: Personalize customer experience | C15: Increase average basket size by 30%
A16: Access proprietary customer data for model training | B16: Improve demand forecasting accuracy | C16: Reduce markdowns by 20%
A17: Joint development of visual style recommender | B17: Boost merchandising differentiation | C17: Co-develop IP & share royalties
A18: 2. Key Deal Terms Matrix
A19: Term | B19: Apparel Position | C19: Partner Position | D19: Agreed Outcome
A20: Contract Length | B20: 3 years | C20: 2 years | D20: 3 years with 2-year renewal option
A21: License Fees | B21: Tiered by usage | C21: Fixed annual | D21: Year 1: $1.2M, Years 2-3: rev-share above 5M sessions
A22: Data Rights | B22: Retain full ownership; limited usage | C22: Shared rights for model training | D22: Partner uses anonymized data; no resale
A23: IP Ownership | B23: Joint IP on co-developed modules | C23: Partner owns all | D23: Joint IP with revenue split 60/40
A24: Service Levels | B24: 99.9% uptime, 24/7 support | C24: 99.5% uptime | D24: 99.9% uptime + penalty credits
A25: Exit Clauses | B25: 60-day cure; data deletion | C25: 90-day | D25: 60-day cure; data purge in 30 days
A26: 3. Risk & Compliance Checklist
A27: Risk Area | B27: Mitigation Strategy | C27: Owner
A28: Data Privacy (GDPR/CCPA) | B28: Privacy impact assessment & DPA | C28: Legal Counsel
A29: Model Bias | B29: Quarterly fairness audit | C29: Chief Data Officer
A30: Performance Failure | B30: SLA penalties up to 15% fees | C30: Procurement Lead
A31: IP Infringement | B31: Mutual indemnity | C31: Both parties
A32: Reputational Risk | B32: Joint comms plan | C32: Marketing Heads
A33: 4. Negotiation Agenda Template
A34: Introductions & goals
A35: Review of strategic objectives
A36: Discussion of key deal terms (Fees, Data, IP, SLAs)
A37: Risk & compliance considerations
A38: Governance & collaboration model
A39: Next steps & action items
A40: 5. Decision & Approval Workflow
...

Sheet GenAI Ethical Decision
A1: GenAI Ethical Decision-Making Checklist
A2: Executive Overview | B2: This comprehensive checklist ensures responsible and ethical implementation of GenAI technologies across all organizational functions. It provides structured guidance for ethical decision-making at every stage of GenAI adoption.
A3: A. Pre-Implementation Ethical Assessment
A4: 1. Purpose and Intent Evaluation
A5: Before implementing any GenAI solution, assess:
A6: Ethical Question | B6: Yes | C6: No | D6: Action Required
A7: Is the intended use of GenAI clearly defined and documented? | B7: ☐ | C7: ☐
A8: Does the GenAI application serve legitimate business objectives? | B8: ☐ | C8: ☐
A9: Could the GenAI system be used for harmful or discriminatory purposes? | B9: ☐ | C9: ☐
A10: Have we considered all stakeholders affected by this GenAI implementation? | B10: ☐ | C10: ☐
A11: Is there a clear business justification that outweighs potential risks? | B11: ☐ | C11: ☐
A12: 2. Stakeholder Impact Analysis
A13: Internal Stakeholders
A14: Stakeholder Group | B14: Potential Impact | C14: Mitigation Strategy | D14: Approval Status
A15: Employees | D15: ☐ Approved ☐ Under Review
A16: Management | D16: ☐ Approved ☐ Under Review
A17: IT Department | D17: ☐ Approved ☐ Under Review
A18: Legal/Compliance | D18: ☐ Approved ☐ Under Review
A19: External Stakeholders
A20: Stakeholder Group | B20: Potential Impact | C20: Mitigation Strategy | D20: Approval Status
A21: Customers | D21: ☐ Approved ☐ Under Review
A22: Suppliers/Partners | D22: ☐ Approved ☐ Under Review
A23: Regulatory Bodies | D23: ☐ Approved ☐ Under Review
A24: Community/Society | D24: ☐ Approved ☐ Under Review
A25: B. Core Ethical Principles Assessment
A26: 1. Transparency and Explainability
A27: Ensure AI systems are transparent and decisions can be explained
A28: Requirement | B28: Status | C28: Evidence/Documentation
A29: AI Disclosure
A30: Is it clearly disclosed when AI is being used? | B30: ☐ Complete ☐ Partial ☐ Missing
A31: Are users informed about AI-generated content/decisions? | B31: ☐ Complete ☐ Partial ☐ Missing
A32: Explainability
A33: Can AI decisions be explained in understandable terms? | B33: ☐ Complete ☐ Partial ☐ Missing
A34: Are explanation mechanisms built into the system? | B34: ☐ Complete ☐ Partial ☐ Missing
A35: Documentation
A36: Is the AI system's functionality clearly documented? | B36: ☐ Complete ☐ Partial ☐ Missing
A37: Are limitations and capabilities clearly stated? | B37: ☐ Complete ☐ Partial ☐ Missing
A38: 2. Fairness and Non-Discrimination
A39: Ensure equitable treatment and prevent bias
A40: Bias Detection Checklist
...

Sheet Change Management Toolkit
A1: GenAI Change Management Toolkit
A2: Overview | B2: This toolkit integrates change management best practices with GenAI adoption, referencing Prosci ADKAR and industry AI guidance. It provides templates, exercises, and communication plans for successful GenAI transformation in an
A3: Context.
A4: A. Change Readiness Assessment
A5: Dimension | B5: Assessment Question | C5: Score (1-5) | D5: Evidence | E5: Action Plan
A6: Awareness | B6: Do employees understand why GenAI is critical?
A7: Desire | B7: Are employees motivated to adopt GenAI tools?
A8: Knowledge | B8: Do employees know how GenAI will change their roles?
A9: Ability | B9: Do employees have the skills to use AI tools?
A10: Reinforcement | B10: Are mechanisms in place to sustain GenAI usage?
A11: Sample Apparel Scores: | B11: Awareness (3), Desire (2), Knowledge (2), Ability (1), Reinforcement (1)
A12: Priority Action:
A13: Launch communication campaign & intensive “AI Stylist Academy” training.
A14: B. Stakeholder Analysis & Engagement Plan
A15: Stakeholder Group | B15: Impact Level (H/M/L) | C15: Influence (H/M/L) | D15: Key Concerns | E15: Engagement Strategy | F15: Owner
A16: Store Associates | B16: H | C16: M | D16: Job displacement, training | E16: In-store demos, training rewards | F16: Change Lead
A17: Merchandising Team | B17: H | C17: H | D17: Data accuracy, workflow change | E17: Pilot involvement, co-design sessions | F17: CDO
A18: E-Commerce Team | B18: H | C18: H | D18: Integration with current CMS | E18: Joint sprint planning | F18: Product Owner
A19: Warehouse Ops | B19: M | C19: M | D19: Forecasting changes | E19: Town halls, dashboards | F19: Ops Director
A20: Executive Board | B20: H | C20: H | D20: ROI, risk management | E20: Monthly scorecards | F20: CIO
A21: C. Communication Plan Template
A22: Audience | B22: Message | C22: Channel | D22: Timing | E22: Owner
A23: All Employees | B23: GenAI Vision & Benefits | C23: CEO Video | D23: Week 1 | E23: CEO
A24: Store Managers | B24: Pilot overview & training schedule | C24: Webinar | D24: Week 2 | E24: HR L&D
A25: Merchandising Analysts | B25: Data flow changes & new dashboard | C25: Workshop | D25: Week 3 | E25: Data Team
A26: Customer Service Reps | B26: AI assistant demo & SOP | C26: E-learning | D26: Week 4 | E26: CS Lead
A27: Suppliers | B27: Forecast accuracy improvement | C27: Newsletter | D27: Week 4 | E27: Supply Chain VP
A28: D. Training & Upskilling Roadmap
A29: Role | B29: Skill Gap | C29: Training Module | D29: Duration | E29: Certification
A30: Store Associate | B30: AI-assisted styling | C30: AI Stylist 101 | D30: 4h self-paced | E30: Digital Badge
A31: Merchant Planner | B31: Forecasting with AI | C31: Demand AI Pro | D31: 2-day workshop | E31: Exam
A32: Data Scientist | B32: Fashion domain knowledge | C32: Apparel 360 | D32: 1-day bootcamp | E32: Certificate
A33: Customer Support | B33: AI copilot chat | C33: SuperAgent AI | D33: 3h webinar | E33: Badge
A34: E. Resistance Management Plan
A35: Expected Resistance | B35: Root Cause | C35: Mitigation Tactic | D35: Owner | E35: Timeline
A36: Fear of job loss | B36: Automation anxiety | C36: Emphasize augmentation, show success stories | D36: HR | E36: Ongoing
A37: Trust in AI recommendations | B37: Black-box perception | C37: Provide explainable AI dashboards | D37: Data Science | E37: Month 2
A38: Data privacy concerns | B38: Customer data usage | C38: Clear policy & training | D38: Legal | E38: Month 1
A39: Skill shortage | B39: Limited AI expertise | C39: Intensive upskilling & mentoring | D39: L&D | E39: Months 1-6
A40: F. Success Metrics & Monitoring
...

Sheet Implementation Roadmap
A1: AI ADOPTION IMPLEMENTATION ROADMAP - ENHANCED
A2: PHASE | B2: QUARTER | C2: PEOPLE INITIATIVES | D2: PROCESS INITIATIVES | E2: TECHNOLOGY INITIATIVES | F2: RESPONSIBLE AI INITIATIVES | G2: CHANGE MGMT INITIATIVES
A3: Foundation | B3: Q1 2026 | C3: Awareness training, skill assessment, leadership alignment, CoE charter planning | D3: Decision tree development, governance setup, risk framework, ethics board formation | E3: Cloud setup, security audit, infrastructure planning, monitoring design | F3: Fairness/XAI tools selected, ethics policy drafted, responsible AI principles defined | G3: Champions identified, incentive program designed, comms cadence launched, pulse surveys begin
A4: Build | B4: Q2 2026 | C4: Upskilling programs, mentoring setup, culture initiatives, CoE hiring, 3-tier training paths | D4: Process documentation, data governance implementation, ethics review workflow | E4: Data warehouse design, ML platform selection, MLOps setup, drift detection designed | F4: Bias testing methodology documented, XAI tools deployed, compliance mapping completed, PIA process live | G4: Champions onboarded, adoption metrics dashboard live, town halls monthly, incentive system active
A5: Pilot | B5: Q3 2026 | C5: Team training on tools, change management execution, mentoring at scale, engagement tracking | D5: Implement governance policies, ethics review process live, data quality ops active, continuous improvement | E5: Deploy selected platforms, integrate systems, set up monitoring, drift detection live, model cards implemented | F5: 70% of models tested for fairness, explainability integrated in 3+ use cases, audit trail active, zero violations | G5: User adoption 60%, CSAT 4.2+, monthly success story series, ambassador network 50+ active, feedback loops closing
A6: Scale | B6: Q4 2026 | C6: Expand programs, build center of excellence fully, hire AI talent, knowledge sharing platform live, 90% adoption | D6: Scale operations, optimize processes continuously, automated governance where possible, process time <8 days | E6: Scale infrastructure 3x, expand ML capabilities, production deployment at scale, cost optimization, 99%+ uptime | F6: 100% model coverage for drift/fairness, regulatory compliance achieved, continuous monitoring, zero violations | G6: 75%+ company-wide adoption, NPS >65, innovation culture embedded, 100+ champions, user feedback drives roadmap
A7: Optimize | B7: 2027 | C7: Continuous learning, knowledge sharing, innovation labs, emerging tech exploration, AI embedded in all roles | D7: Continuous improvement, process optimization, governance maturity (self-service approvals), industry benchmarking | E7: Advanced analytics, AI-driven insights, full automation, cost per prediction optimized, cutting-edge infrastructure | F7: Advanced responsible AI (federated learning, synthetic data), continuous bias monitoring, regulatory leadership, thought leadership | G7: AI as business-as-usual, internal marketplace for models, customer-facing AI products, startup partnerships
A8: TOTAL INVESTMENT 2026
A9: EXPECTED ROI 2026-2027
A10: CRITICAL SUCCESS FACTORS
A11: Factor | B11: Owner | C11: Q1 Completion | D11: Q2 Completion | E11: Q3 Completion | F11: Q4 Completion | G11: Status
A12: Executive Sponsorship | B12: CEO/COO | C12: 100% aligned | D12: Active leadership | E12: Weekly reviews | F12: Strategic ownership | G12: In Progress
A13: Governance Effectiveness | B13: CIO | C13: Committee operational | D13: 4+ decisions made | E13: Escalation process tested | F13: Fully autonomous | G13: In Progress
A14: Data Quality | B14: CDO | C14: >75% | D14: >85% | E14: >95% | F14: 98%+ | G14: In Progress
A15: Skill Development | B15: HR Lead | C15: 30% in training | D15: 50% certified | E15: 75% certified | F15: 90% certified | G15: In Planning
A16: Responsible AI Compliance | B16: Legal/Ethics | C16: Board formed, policy drafted | D16: Fairness testing >20% | E16: 70% models reviewed | F16: 100% models compliant | G16: In Planning
A17: Use Case Momentum | B17: Program Lead | C17: 2 quick wins approved | D17: Models 50% complete | E17: 4 models in production | F17: 8 models live | G17: In Planning
A18: Adoption & Change | B18: Change Manager | C18: 40% awareness | D18: 40% adoption | E18: 60% adoption | F18: 75% adoption | G18: In Planning
A19: Infrastructure Readiness | B19: IT Lead | C19: Cloud approved | D19: DW designed | E19: Platforms live | F19: Scaled 3x | G19: In Planning
